Traceback (most recent call last):
  File "/Users/kellymorrow/anaconda3/lib/python3.7/site-packages/jupyter_cache/executors/utils.py", line 56, in single_nb_execution
    record_timing=False,
  File "/Users/kellymorrow/anaconda3/lib/python3.7/site-packages/nbclient/client.py", line 1077, in execute
    return NotebookClient(nb=nb, resources=resources, km=km, **kwargs).execute()
  File "/Users/kellymorrow/anaconda3/lib/python3.7/site-packages/nbclient/util.py", line 74, in wrapped
    return just_run(coro(*args, **kwargs))
  File "/Users/kellymorrow/anaconda3/lib/python3.7/site-packages/nbclient/util.py", line 53, in just_run
    return loop.run_until_complete(coro)
  File "/Users/kellymorrow/anaconda3/lib/python3.7/asyncio/base_events.py", line 587, in run_until_complete
    return future.result()
  File "/Users/kellymorrow/anaconda3/lib/python3.7/site-packages/nbclient/client.py", line 527, in async_execute
    cell, index, execution_count=self.code_cells_executed + 1
  File "/Users/kellymorrow/anaconda3/lib/python3.7/site-packages/nbclient/client.py", line 822, in async_execute_cell
    self._check_raise_for_error(cell, exec_reply)
  File "/Users/kellymorrow/anaconda3/lib/python3.7/site-packages/nbclient/client.py", line 730, in _check_raise_for_error
    raise CellExecutionError.from_cell_and_msg(cell, exec_reply['content'])
nbclient.exceptions.CellExecutionError: An error occurred while executing the following cell:
------------------
# import libraries
library(dplyr)
library(ggplot2)
library(tidyr)

# import data
df <- read.table('../data_examples/MAX101_Main_block_MR_I_gPPI_demean.x1D')
------------------

Error in file(file, "rt"): cannot open the connection
Traceback:

1. read.table("../data_examples/MAX101_Main_block_MR_I_gPPI_demean.x1D")
2. file(file, "rt")
ERROR: Error in file(file, "rt"): cannot open the connection


